Workbook
Name Auditor: 'P. Input'!#REF!
Name CompanyName: 'P. Input'!$C$2
Name Currency: 'P. Input'!$C$6
Name DealStartDate: #REF!
Name EX_Yr1: 'P. Input'!$C$12
Name FinancialYearEnd: 'P. Input'!$C$3
Name FX_Yr1: 'P. Input'!$C$12
Name FX_Yr2: 'P. Input'!$D$12
Name FX_Yr3: #REF!
Name FX_Yr4: #REF!
Name FX_Yr5: #REF!
Name FX_Yr6: #REF!
Name FX_Yr7: #REF!
Name FX_Yr8: #REF!
Name Input_Multiplier: 'P. Input'!$C$7
Name NumPriorAnnualReportsRecorded: 'P. Input'!$C$5
Name PreviousFinancialYearEnd: 'P. Input'!$C$4
Name Reporting_Multiplier: 'P. Input'!$C$9
Name Units_Multiplier: 'P. Input'!$G$9

Sheet P. Input
E1: LEGEND
B2: Company Name | C2: Green Solutions Manufacturing Ltd. | E2: Parameters
B3: Financial Year End | C3: 45291 | E3: User Inputs
B4: Date Of Previous Financial Year End | C4: 44926 | E4: Output
B5: # of Prior Year Annual Reports Recorded | C5: 1
B6: Input Currency | C6: £ | F6: Ones | G6: 1
B7: Input Multiplier | C7: Thousands | D7: =$C$6&IF($C7="Ones","",IF($C7="Thousands","'K","'M")) -> £'K | F7: Thousands | G7: 1000
C8: $ | F8: Millions | G8: 1000000
C9: Thousands | D9: =$C$6&IF($C9="Ones","",IF($C9="Thousands","'K","'M")) -> £'K | E9: =$C$8&IF($C9="Ones","",IF($C9="Thousands","'K","'M")) -> $'K | F9: Units Multiplier | G9: =VLOOKUP(Input_Multiplier,F6:G8,2,FALSE)/VLOOKUP(Reporting_Multiplier,F6:G8,2,FALSE) -> 1
B11: Exchange Rate | C11: =EDATE(FinancialYearEnd,-12*NumPriorAnnualReportsRecorded) -> 44926 | D11: =EDATE(C11,12) -> 45291
B12: =Currency&"-->"&C8 -> £-->$ | C12: 1 | D12: 1

Sheet I. Profit_Loss
A1: =CompanyName -> Green Solutions Manufacturing Ltd.
A2: Income Statement
B3: =IF(B$4<=FinancialYearEnd,"Actual","Forecast") -> Actual | C3: =IF(C$4<=FinancialYearEnd,"Actual","Forecast") -> Actual
A4: ='P. Input'!$D$7 -> £'K | B4: =EDATE(FinancialYearEnd,-12*NumPriorAnnualReportsRecorded) -> 44926 | C4: =EDATE(B4,12) -> 45291
A5: Revenue | B5: 31536 | C5: 53823
A6: Cost of sales | B6: 24906 | C6: 40217
A7: Efficiency Ratio | B7: =IFERROR(ABS(B$6)/B$5,"-") -> 0.78976408 | C7: =IFERROR(ABS(C$6)/C$5,"-") -> 0.74720844
A8: Gross Profit | B8: =B5-B6 -> 6630 | C8: =C5-C6 -> 13606
A9: Research and development | B9: 1491 | C9: 2593
A10: Selling, general and administrative | B10: 3145 | C10: 4517
A11: Restructuring and other | B11: 0 | C11: -27
A12: Income (loss) from operations | B12: =B8-SUM(B9:B11) -> 1994 | C12: =C8-SUM(C9:C11) -> 6523
A13: Interest income | B13: 30 | C13: 56
A14: Interest expense | B14: -748 | C14: -371
A15: Other income (expense), net | B15: -122 | C15: 135
A16: Profit Before Tax (PBT) | B16: =B12+SUM(B13:B15) -> 1154 | C16: =C12+SUM(C13:C15) -> 6343
A17: Tax | B17: 292 | C17: 699
A18: Profit After Tax (PAT) | B18: =B16-B17 -> 862 | C18: =C16-C17 -> 5644
A19: Net income attributable to noncontrolling interests and redeemable noncontrolling interests in subsidiaries | B19: 141 | C19: 125
A20: Total Comprehensive (loss)/ income | B20: =B18-B19 -> 721 | C20: =C18-C19 -> 5519
A23: EBITDA computation
A24: Operating profit | B24: =B12 -> 1994 | C24: =C12 -> 6523
A25: Depreciation & Amortisation | B25: =SUM(B26:B27) -> -500 | C25: =SUM(C26:C27) -> -1000
A26: Depreciation | B26: -500 | C26: -1000
A27: Amortisation
A28: EBITDA | B28: =B24+B25 -> 1494 | C28: =C24+C25 -> 5523
A29: EBITDA Margin | B29: =IFERROR(B28/B5,"-") -> 0.047374429 | C29: =IFERROR(C28/C5,"-") -> 0.10261412

Sheet I. Balance_Sheet
A1: =CompanyName -> Green Solutions Manufacturing Ltd.
A2: Balance Sheet
B3: =IF(B$4<=FinancialYearEnd,"Actual","Forecast") -> Actual | C3: =IF(C$4<=FinancialYearEnd,"Actual","Forecast") -> Actual
A4: ='P. Input'!$D$7 -> £'K | B4: =EDATE(FinancialYearEnd,-12*NumPriorAnnualReportsRecorded) -> 44926 | C4: =EDATE(B4,12) -> 45291
A5: Assets
A7: Non-Current Assets
A8: Operating lease vehicles, net | B8: 3091 | C8: 4511
A9: Solar energy systems, net | B9: 5979 | C9: 5765
A10: Property, plant and equipment, net | B10: 12747 | C10: 18884
A11: Operating lease right-of-use assets | B11: 1558 | C11: 2016
A12: Digital assets, net | B12: 0 | C12: 1260
A13: Intangible assets, net | B13: 313 | C13: 257
A14: Goodwill | B14: 207 | C14: 200
A15: Other non-current assets | B15: 1536 | C15: 2138
A16: Total Non-Current Assets | B16: =SUM(B8:B15) -> 25431 | C16: =SUM(C8:C15) -> 35031
A18: Current Assets
A19: Cash and cash equivalents | B19: 19384 | C19: 17576
A20: Short-term marketable securities | B20: 0 | C20: 131
A21: Accounts receivable, net | B21: 1886 | C21: 1913
A22: Inventories | B22: 4101 | C22: 5757
A23: Prepaid expenses and other current assets | B23: 1346 | C23: 1723
A24: Total Current Assets | B24: =SUM(B19:B23) -> 26717 | C24: =SUM(C19:C23) -> 27100
A26: Total Assets | B26: =B16+B24 -> 52148 | C26: =C16+C24 -> 62131
A28: Liabilities & Equity
A30: Liabilities
A32: Current Liabilities
A33: Accounts payable | B33: 6051 | C33: 10025
A34: Accrued liabilities and other | B34: 3855 | C34: 5719
A35: Deferred revenue | B35: 1458 | C35: 1447
A36: Customer deposits | B36: 752 | C36: 925
A37: Current portion of debt and finance leases | B37: 2132 | C37: 1589
A38: Total Current Liabilities | B38: =SUM(B33:B37) -> 14248 | C38: =SUM(C33:C37) -> 19705
A40: Non-Current Liabilities
A41: Debt and finance leases, net of current portion | B41: 9556 | C41: 5245
A42: Deferred revenue, net of current portion | B42: 1284 | C42: 2052
A43: Other long-term liabilities | B43: 3330 | C43: 3546
A44: Total Non-Current Liabilities | B44: =SUM(B41:B43) -> 14170 | C44: =SUM(C41:C43) -> 10843
A46: Total Liabilities | B46: =B38+B44 -> 28418 | C46: =C38+C44 -> 30548
A48: Redeemable noncontrolling interests in subsidiaries | B48: 604 | C48: 568
A49: Convertible senior notes (Note 11) | B49: 51 | C49: 0
...

Sheet I. Cashflow
A1: =CompanyName -> Green Solutions Manufacturing Ltd.
A2: Cash Flow Statement
B3: =IF(B$4<=FinancialYearEnd,"Actual","Forecast") -> Actual | C3: =IF(C$4<=FinancialYearEnd,"Actual","Forecast") -> Actual
A4: ='P. Input'!$D$7 -> £'K | B4: =EDATE(FinancialYearEnd,-12*NumPriorAnnualReportsRecorded) -> 44926 | C4: =EDATE(B4,12) -> 45291
A5: Cash Flows from Operating Activities
A6: Net income (loss) | B6: ='I. Profit_Loss'!B18 -> 862 | C6: ='I. Profit_Loss'!C18 -> 5644
A7: Adjustments to reconcile net income (loss) to net cash provided by operating activities:
A8: Depreciation, amortization and impairment | B8: 2322 | C8: 2911
A9: Stock-based compensation | B9: 1734 | C9: 2121
A10: Inventory and purchase commitments write-downs | B10: 202 | C10: 140
A11: Foreign currency transaction net unrealized (gain) loss | B11: 114 | C11: -55
A12: Non-cash interest and other operating activities | B12: 525 | C12: 245
A13: Digital assets gain, net | B13: 0 | C13: =-27-51 -> -78
A14: Operating cash flow related to repayment of discounted convertible senior notes | B14: 0
A15: Changes in operating assets and liabilities:
A16: Accounts receivable | B16: -652 | C16: -130
A17: Inventory | B17: -422 | C17: -1709
A18: Operating lease vehicles | B18: -1072 | C18: -2114
A19: Prepaid expenses and other current assets | B19: -251 | C19: -271
A20: Other non-current assets | B20: -344 | C20: -1291
A21: Accounts payable and accrued liabilities | B21: 2102 | C21: 4578
A22: Deferred revenue | B22: 321 | C22: 793
A23: Customer deposits | B23: 7 | C23: 186
A24: Other long-term liabilities | B24: 495 | C24: 476
A25: Net cash provided by operating activities | B25: =SUM(B6:B24) -> 5943 | C25: =SUM(C6:C24) -> 11446
A27: Cash Flows from Investing Activities
A28: Purchases of property and equipment excluding finance leases, net of sales | B28: -3157 | C28: -6482
A29: Purchases of solar energy systems, net of sales | B29: -75 | C29: -32
A30: Purchases of digital assets | B30: 0 | C30: -1500
A31: Proceeds from sales of digital assets | B31: 0 | C31: 272
A32: Purchases of marketable securities | B32: 0 | C32: -132
A33: Receipt of government grants | B33: 123 | C33: 6
A34: Purchase of intangible assets | B34: -10 | C34: 0
A35: Business combinations, net of cash acquired | B35: -13 | C35: 0
A36: Net cash used in investing activities | B36: =SUM(B28:B35) -> -3132 | C36: =SUM(C28:C35) -> -7868
A38: Cash Flows from Financing Activities
A39: Proceeds from issuances of common stock in public offerings, net of issuance costs | B39: 12269 | C39: 0
A40: Proceeds from issuances of convertible and other debt | B40: 9713 | C40: 8883
A41: Repayments of convertible and other debt | B41: -11623 | C41: -14167
A42: Collateralized lease repayments | B42: -240 | C42: -9
...

Sheet O. Report
A1: =CompanyName -> Green Solutions Manufacturing Ltd.
A2: Report
B3: =IF(B$4<=FinancialYearEnd,"Actual","Forecast") -> Actual | C3: =IF(C$4<=FinancialYearEnd,"Actual","Forecast") -> Actual
A4: ='P. Input'!D9 -> £'K | B4: =EDATE(FinancialYearEnd,-12*NumPriorAnnualReportsRecorded) -> 44926 | C4: =EDATE(B4,12) -> 45291 | D4: Comments
A5: Financial Performance
A6: Total Revenue | B6: ='I. Profit_Loss'!B5*Units_Multiplier -> 31536 | C6: ='I. Profit_Loss'!C5*Units_Multiplier -> 53823 | D6: Total Revenue increased ~71% on YoY basis, primarily driven by surge in demand.
A7: EBITDA | B7: ='I. Profit_Loss'!B28*Units_Multiplier -> 1494 | C7: ='I. Profit_Loss'!C28*Units_Multiplier -> 5523 | D7: Significant increase in EBITDA mainly driven by improvement in Gross Margins and increase in Revenue.
A8: Net Interest Expense | B8: =('I. Profit_Loss'!B13+'I. Profit_Loss'!B14)*Units_Multiplier -> -718 | C8: =('I. Profit_Loss'!C13+'I. Profit_Loss'!C14)*Units_Multiplier -> -315 | D8: Net Interest Expense have almost halved due to a drop in interest expense and an increase in interest income.
A9: Net Profit/(Loss) Before Tax | B9: ='I. Profit_Loss'!B16*Units_Multiplier -> 1154 | C9: ='I. Profit_Loss'!C16*Units_Multiplier -> 6343 | D9: In line with topline growth and cost controls, NPBT and NPAT grew materially.
A10: Net Profit/(Loss) After Tax | B10: ='I. Profit_Loss'!B18*Units_Multiplier -> 862 | C10: ='I. Profit_Loss'!C18*Units_Multiplier -> 5644 | D10: Similar % increase to Net Profit Before Tax.
A12: Financial Position
A13: Total Assets (Including Intangibles) | B13: ='I. Balance_Sheet'!B26*Units_Multiplier -> 52148 | C13: ='I. Balance_Sheet'!C26*Units_Multiplier -> 62131 | D13: Balance sheet expanded ~19% YoY basis, and is primarily dominated by increase in property, plant, and equipment (~50%) which is in line with manufacturer model
A14: Total Tangible Assets (TTA) | B14: =('I. Balance_Sheet'!B26-'I. Balance_Sheet'!B13-'I. Balance_Sheet'!B14)*Units_Multiplier -> 51628 | C14: =('I. Balance_Sheet'!C26-'I. Balance_Sheet'!C13-'I. Balance_Sheet'!C14)*Units_Multiplier -> 61674 | D14: Similar to Total Asset, a slight increase in Total Tangible Assets
A15: Inventories | B15: ='I. Balance_Sheet'!B22*Units_Multiplier -> 4101 | C15: ='I. Balance_Sheet'!C22*Units_Multiplier -> 5757 | D15: A sizable 40% increase in inventory during 2023 is consistent with the increase in sales during the year.
A16: Cash and cash equivalents | B16: ='I. Balance_Sheet'!B19*Units_Multiplier -> 19384 | C16: ='I. Balance_Sheet'!C19*Units_Multiplier -> 17576 | D16: Cash reserves reduced YoY primarily to support CAPEX investments & debt repayments.
A17: Total Liabilities | B17: ='I. Balance_Sheet'!B46*Units_Multiplier -> 28418 | C17: ='I. Balance_Sheet'!C46*Units_Multiplier -> 30548 | D17: A slight increase in total liabilities
A18: Net Worth (inc intangibles) (NW) | B18: =(B13-B17) -> 23730 | C18: =(C13-C17) -> 31583 | D18: Net worth increased on the back of continued profit accumulation. No signs of capital leakages.
A19: Tangible Net Worth (TNW) | B19: =(B14-B17) -> 23210 | C19: =(C14-C17) -> 31126 | D19: Consistent with the movement in Net Worth, Tangible Net Worth has also increased by c.34% over the year.
A21: Cash Flows
A22: Net Cash in/(out)flow from operating activities | B22: ='I. Cashflow'!B25*Units_Multiplier -> 5943 | C22: ='I. Cashflow'!C25*Units_Multiplier -> 11446 | D22: Positive cash flow generated from operating activities has almost doubled over the year.
A23: Capital Expenditure | B23: =SUM('I. Cashflow'!B28:B30,'I. Cashflow'!B34) -> -3242 | C23: =SUM('I. Cashflow'!C28:C30,'I. Cashflow'!C34) -> -8014 | D23: Capital Expenditure has increased since 2022, mainly driven by purchase of property and equipment.
A24: Free Cash Flow | B24: =SUM(B22:B23) -> 2701 | C24: =SUM(C22:C23) -> 3432 | D24: Free Cash Flow has increased due to increase in net cashflow from operating activities which was partially offset by increase in Capital Expenditure.
A26: Ratios
A27: EBITDA Margin | B27: =IFERROR(B7/B6,"N/A") -> 0.047374429 | C27: =IFERROR(C7/C6,"N/A") -> 0.10261412 | D27: EBITDA Margin almost doubled in 2023. Indicating improved profitability.
A28: Operating Margin | B28: =IFERROR('I. Profit_Loss'!B12/'I. Profit_Loss'!B5,"N/A") -> 0.063229325 | C28: =IFERROR('I. Profit_Loss'!C12/'I. Profit_Loss'!C5,"N/A") -> 0.12119354 | D28: Similarly, Operating Margin has doubled indicating improvements in efficiency.
A29: EBITDA Net Interest Cover (x) | B29: =IFERROR(IF(B7<0,"N/A",B7/-B8),"N/A") -> 2.0807799 | C29: =IFERROR(IF(C7<0,"N/A",C7/-C8),"N/A") -> 17.533333 | D29: Significant improvement as the EBITDA increased while Net Interest Payments dropped. The higher this number, the better it is for the business.
A30: Current Ratio i.e. Current Assets / Current Liabilities (%) | B30: =IFERROR('I. Balance_Sheet'!B24/'I. Balance_Sheet'!B38,"N/A") -> 1.8751404 | C30: =IFERROR('I. Balance_Sheet'!C24/'I. Balance_Sheet'!C38,"N/A") -> 1.3752855 | D30: Current Asset Ratio has slightly dropped, indicating a drop in current assets relative to current liabilities.
A31: Leverage Metric | B31: =SUM('I. Balance_Sheet'!B37,'I. Balance_Sheet'!B41)/'I. Profit_Loss'!B28 -> 7.8232932 | C31: =SUM('I. Balance_Sheet'!C37,'I. Balance_Sheet'!C41)/'I. Profit_Loss'!C28 -> 1.237371 | D31: Leverage Metric has decreased by c.6.6 (i.e., 84%), mainly due to a significant increase in EBITDA and a limited increase in liabilities. | E31: =B31-C31 -> 6.5859222
A32: Net Leverage | B32: =(SUM('I. Balance_Sheet'!B37,'I. Balance_Sheet'!B41)-'I. Balance_Sheet'!B19)/'I. Profit_Loss'!B28 -> -5.1512718 | C32: =(SUM('I. Balance_Sheet'!C37,'I. Balance_Sheet'!C41)-'I. Balance_Sheet'!C19)/'I. Profit_Loss'!C28 -> -1.9449575 | D32: Net Leverage has increased by c.3.2 (i.e., 62%), mainly driven by an improvement in Leverage Metric but partially offset by a decrease in cash balance over the year.
A33: Cash flow to capital expenditures (CF/CapEX) | B33: =B22/B23 -> -1.8331277 | C33: =C22/C23 -> -1.4282506 | D33: CF/CapEX has changed by 0.4 due to increased capital expenditure relative to cashflows generated from operating activities.
